Workbook
Name Slicer_Demand_Category: #N/A
Name Slicer_hr: #N/A
Name Slicer_Rash_Hour: #N/A
Name Slicer_Times_of_Day: #N/A
Name Slicer_Times_of_Day1: #N/A
Name Slicer_Weather: #N/A
Name Slicer_weathersit: #N/A
Name Slicer_Weekday_By_Name: #N/A
Name Slicer_Weekday_By_Name1: #N/A

Sheet Final D Week Vs Demand HeadMap
A3: Sum of cnt | B3: Column Labels
A4: Row Labels | B4: 0 | C4: 1 | D4: 2 | E4: 3 | F4: 4 | G4: 5 | H4: 6 | I4: (blank) | J4: Grand Total
A5: 0 | B5: 214 | C5: 67 | D5: 44 | E5: 52 | F5: 59 | G5: 88 | H5: 179 | J5: 703
A6: 1 | B6: 162 | C6: 39 | D6: 17 | E6: 34 | F6: 23 | G6: 35 | H6: 150 | J6: 460
A7: 2 | B7: 105 | C7: 17 | D7: 10 | E7: 23 | F7: 11 | G7: 10 | H7: 118 | J7: 294
A8: 3 | B8: 63 | C8: 9 | D8: 3 | E8: 3 | F8: 5 | G8: 4 | H8: 64 | J8: 151
A9: 4 | B9: 10 | C9: 14 | D9: 6 | E9: 5 | F9: 7 | G9: 2 | H9: 25 | J9: 69
A10: 5 | B10: 10 | C10: 33 | D10: 24 | E10: 26 | F10: 21 | G10: 33 | H10: 17 | J10: 164
A11: 6 | B11: 11 | C11: 174 | D11: 160 | E11: 150 | F11: 164 | G11: 146 | H11: 17 | J11: 822
A12: 7 | B12: 26 | C12: 503 | D12: 453 | E12: 410 | F12: 454 | G12: 443 | H12: 50 | J12: 2339
A13: 8 | B13: 102 | C13: 967 | D13: 1012 | E13: 946 | F13: 1036 | G13: 1178 | H13: 147 | J13: 5388
A14: 9 | B14: 229 | C14: 561 | D14: 625 | E14: 609 | F14: 659 | G14: 785 | H14: 204 | J14: 3672
A15: 10 | B15: 497 | C15: 296 | D15: 246 | E15: 291 | F15: 227 | G15: 314 | H15: 382 | J15: 2253
A16: 11 | B16: 599 | C16: 286 | D16: 254 | E16: 267 | F16: 273 | G16: 337 | H16: 478 | J16: 2494
... A28: 23 | B28: 134 | C28: 100 | D28: 118 | E28: 136 | F28: 157 | G28: 176 | H28: 262 | J28: 1083
A29: (blank)
A30: Grand Total | B30: 8121 | C30: 8450 | D30: 8383 | E30: 8049 | F30: 8458 | G30: 9095 | H30: 7748 | J30: 58304

Sheet Final D Temparature Bin
A3: Row Labels | B3: Average of casual | C3: Average of registered | D3: Average of cnt
A4: Cold (20-30%) | B4: 4.5400458 | C4: 55.455378 | D4: 59.995423
A5: Freezing (0-10%) | B5: 1.8627451 | C5: 27.941176 | D5: 29.803922
A6: Mild (30-40%) | B6: 13.971429 | C6: 79.904762 | D6: 93.87619
A7: Very Cold (10-20%) | B7: 2.3395722 | C7: 47.783422 | D7: 50.122995
A8: Warm (40-50%) | B8: 15.151515 | C8: 44.333333 | D8: 59.484848
A9: (blank)
A10: Grand Total | B10: 4.921 | C10: 53.383 | D10: 58.304

Sheet Fin D Actual VS Forecasted
A1: Row Labels | B1: Sum of Cnt | C1: Sum of Forecast(Cnt)
A2: 01-Jan | B2: 985
A3: 02-Jan | B3: 801
A4: 03-Jan | B4: 1349
A5: 04-Jan | B5: 1562
A6: 05-Jan | B6: 1600
A7: 06-Jan | B7: 1606
A8: 07-Jan | B8: 1510
A9: 08-Jan | B9: 959
A10: 09-Jan | B10: 822
A11: 10-Jan | B11: 1321
A12: 11-Jan | B12: 1263
A13: 12-Jan | B13: 1162
... A45: 13-Feb | B45: 1589
A46: 14-Feb | B46: 151 | C46: 151
A47: 15-Feb | C47: 1387.2167
A48: 16-Feb | C48: 1392.5598
A49: 17-Feb | C49: 1397.9028
A50: 18-Feb | C50: 1403.2458
A51: 19-Feb | C51: 1408.5889
A52: 20-Feb | C52: 1413.9319
A53: 21-Feb | C53: 1419.2749
A54: Grand Total | B54: 58304 | C54: 9973.7208

Sheet Final D Demand forcusting
A1: Date | B1: Cnt
A2: 40544 | B2: =SUMIF('Final Dataset'!B:B,A2,'Final Dataset'!P:P) -> 985
A3: 40545 | B3: =SUMIF('Final Dataset'!B:B,A3,'Final Dataset'!P:P) -> 801
A4: 40546 | B4: =SUMIF('Final Dataset'!B:B,A4,'Final Dataset'!P:P) -> 1349
A5: 40547 | B5: =SUMIF('Final Dataset'!B:B,A5,'Final Dataset'!P:P) -> 1562
A6: 40548 | B6: =SUMIF('Final Dataset'!B:B,A6,'Final Dataset'!P:P) -> 1600
A7: 40549 | B7: =SUMIF('Final Dataset'!B:B,A7,'Final Dataset'!P:P) -> 1606
A8: 40550 | B8: =SUMIF('Final Dataset'!B:B,A8,'Final Dataset'!P:P) -> 1510
A9: 40551 | B9: =SUMIF('Final Dataset'!B:B,A9,'Final Dataset'!P:P) -> 959
A10: 40552 | B10: =SUMIF('Final Dataset'!B:B,A10,'Final Dataset'!P:P) -> 822
A11: 40553 | B11: =SUMIF('Final Dataset'!B:B,A11,'Final Dataset'!P:P) -> 1321
A12: 40554 | B12: =SUMIF('Final Dataset'!B:B,A12,'Final Dataset'!P:P) -> 1263
A13: 40555 | B13: =SUMIF('Final Dataset'!B:B,A13,'Final Dataset'!P:P) -> 1162
... A46: 40588 | B46: =SUMIF('Final Dataset'!B:B,A46,'Final Dataset'!P:P) -> 151
A47: 40589 | B47: =_xlfn.FORECAST.LINEAR(A47,B2:B46,A2:A46) -> 1381.8838
A48: 40590 | B48: =_xlfn.FORECAST.LINEAR(A48,B2:B47,A2:A47) -> 1385.6334
A49: 40591 | B49: =_xlfn.FORECAST.LINEAR(A49,B4:B48,A4:A48) -> 1358.115
A50: 40592 | B50: =_xlfn.FORECAST.LINEAR(A50,B5:B49,A5:A49) -> 1363.2267
A51: 40593 | B51: =_xlfn.FORECAST.LINEAR(A51,B6:B50,A6:A50) -> 1378.8773
A52: 40594 | B52: =_xlfn.FORECAST.LINEAR(A52,B7:B51,A7:A51) -> 1398.3254
A53: 40595 | B53: =_xlfn.FORECAST.LINEAR(A53,B8:B52,A8:A52) -> 1420.4571

Sheet Final d Rides by hour 
A3: Row Labels | B3: Average of cnt | C3: Average of registered | D3: Average of casual
A4: 0 | B4: 16.348837 | C4: 14.627907 | D4: 1.7209302
A5: 1 | B5: 10.697674 | C5: 9.5813953 | D5: 1.1162791
A6: 2 | B6: 7.1707317 | C6: 6.3658537 | D6: 0.80487805
A7: 3 | B7: 4.8709677 | C7: 3.7741935 | D7: 1.0967742
A8: 4 | B8: 2.15625 | C8: 1.9375 | D8: 0.21875
A9: 5 | B9: 4.2051282 | C9: 4.1282051 | D9: 0.076923077
A10: 6 | B10: 19.571429 | C10: 19.071429 | D10: 0.5
A11: 7 | B11: 54.395349 | C11: 52.906977 | D11: 1.4883721
A12: 8 | B12: 128.28571 | C12: 125.2619 | D12: 3.0238095
A13: 9 | B13: 87.428571 | C13: 83.333333 | D13: 4.0952381
A14: 10 | B14: 53.642857 | C14: 48.5 | D14: 5.1428571
A15: 11 | B15: 59.380952 | C15: 50.642857 | D15: 8.7380952
... A27: 23 | B27: 25.186047 | C27: 22.837209 | D27: 2.3488372
A28: Grand Total | B28: 58.304 | C28: 53.383 | D28: 4.921

Sheet Final D Rides by Weather
A1: holiday | B1: (All)
A3: Row Labels | B3: Sum of casual | C3: Sum of registered | D3: Average of cnt
A4: Dark Cloude | B4: 171 | C4: 2618 | D4: 33.202381
A5: Mild Cold | B5: 3211 | C5: 34162 | D5: 61.671617
A6: More Than Mild | B6: 1538 | C6: 16568 | D6: 58.595469
A7: Thander Storm | B7: 1 | C7: 35 | D7: 36
A8: Grand Total | B8: 4921 | C8: 53383 | D8: 58.304

Sheet FinalD RidesVsWeekday&Demand
A3: Average of cnt | B3: Column Labels
A4: Row Labels | B4: High | C4: Low | D4: Medium | E4: Grand Total
A5: Sunday | B5: 174 | C5: 20.94898 | D5: 82.402985 | E5: 46.674699
A6: Monday | B6: 165 | C6: 19.121212 | D6: 84.696429 | E6: 49.518293
A7: Tuesday | B7: 175.06667 | C7: 17.421053 | D7: 77.586207 | E7: 56.711409
A8: Wednesday | B8: 199.16667 | C8: 19.947368 | D8: 83.724138 | E8: 66.007874
A9: Thursday | B9: 180.91667 | C9: 21.698413 | D9: 80.553571 | E9: 61.442748
A10: Friday | B10: 184.64286 | C10: 20.037037 | D10: 84.052632 | E10: 67.664
A11: Saturday | B11: 185.42857 | C11: 19.8 | D11: 82.984375 | E11: 65.905797
A12: Grand Total | B12: 182.16883 | C12: 19.810651 | D12: 82.290865 | E12: 58.304

Sheet FinalD Times of a day
A1: Rash Hour | B1: (All)
A3: Row Labels | B3: Sum of cnt | C3: Sum of registered | D3: Sum of casual
A4: Afternoon | B4: 23308 | C4: 20423 | D4: 2885
A5: Evening | B5: 16187 | C5: 15317 | D5: 870
A6: Morning | B6: 16968 | C6: 16001 | D6: 967
A7: Night | B7: 1841 | C7: 1642 | D7: 199
A8: Grand Total | B8: 58304 | C8: 53383 | D8: 4921

Sheet Final D Dashboard
A1: 🚲 BIKE SHARING DEMAND DASHBOARD | B1: 🚲 BIKE SHARING DEMAND DASHBOARD | C1: 🚲 BIKE SHARING DEMAND DASHBOARD | D1: 🚲 BIKE SHARING DEMAND DASHBOARD | E1: 🚲 BIKE SHARING DEMAND DASHBOARD | F1: 🚲 BIKE SHARING DEMAND DASHBOARD | G1: 🚲 BIKE SHARING DEMAND DASHBOARD | H1: 🚲 BIKE SHARING DEMAND DASHBOARD | I1: 🚲 BIKE SHARING DEMAND DASHBOARD | J1: 🚲 BIKE SHARING DEMAND DASHBOARD | K1: 🚲 BIKE SHARING DEMAND DASHBOARD | L1: 🚲 BIKE SHARING DEMAND DASHBOARD | M1: 🚲 BIKE SHARING DEMAND DASHBOARD | N1: 🚲 BIKE SHARING DEMAND DASHBOARD | O1: 🚲 BIKE SHARING DEMAND DASHBOARD | P1: 🚲 BIKE SHARING DEMAND DASHBOARD
A4: Total Rides | C4: Average Rides/Hour | E4: Peak Hour | G4: Holiday Hours | I4: Registered Share | K4: Casual Share
A5: =SUM('Final Dataset'!P:P) -> 58304 | C5: =AVERAGE('Final Dataset'!P:P) -> 58.304 | E5: =INDEX('Final Dataset'!F:F, MATCH(MAX('Final Dataset'!P:P), 'Final Dataset'!P:P, 0))&":00" -> 8:00 | G5: =COUNTIF('Final Dataset'!G:G, TRUE) -> 24 | I5: =SUM('Final Dataset'!O:O)/SUM('Final Dataset'!P:P) -> 0.91559756 | K5: =SUM('Final Dataset'!N:N)/SUM('Final Dataset'!P:P) -> 0.084402442
A7: across full dataset | C7: system-wide average | E7: highest avg demand hour | G7: flagged holiday hours | I7: of total rides | K7: of total rides

Sheet FiDAverage Rides by Hour of Day
A3: Row Labels | B3: Average of cnt
A4: 0 | B4: 16.348837
A5: 1 | B5: 10.697674
A6: 2 | B6: 7.1707317
A7: 3 | B7: 4.8709677
A8: 4 | B8: 2.15625
A9: 5 | B9: 4.2051282
A10: 6 | B10: 19.571429
A11: 7 | B11: 54.395349
A12: 8 | B12: 128.28571
A13: 9 | B13: 87.428571
A14: 10 | B14: 53.642857
A15: 11 | B15: 59.380952
... A27: 23 | B27: 25.186047
A28: Grand Total | B28: 58.304

Sheet FinDOve Average Rides by Weekda
A3: Row Labels | B3: Average of cnt
A4: Sunday | B4: 46.674699
A5: Monday | B5: 49.518293
A6: Tuesday | B6: 56.711409
A7: Wednesday | B7: 66.007874
A8: Thursday | B8: 61.442748
A9: Friday | B9: 67.664
A10: Saturday | B10: 65.905797
A11: Grand Total | B11: 58.304

Sheet FinDAvgRidesinHigh-Demand Hours
A1: Demand Category | B1: (Multiple Items)
A3: Row Labels | B3: Average of cnt
A4: Sunday | B4: 46.674699
A5: Monday | B5: 49.518293
A6: Tuesday | B6: 56.711409
A7: Wednesday | B7: 66.007874
A8: Thursday | B8: 61.442748
A9: Friday | B9: 67.664
A10: Saturday | B10: 65.905797
A11: Grand Total | B11: 58.304

Sheet finD Avg Rid by Weath Con
A3: Row Labels | B3: Average of cnt
A4: Dark Cloude | B4: 33.202381
A5: Mild Cold | B5: 61.671617
A6: More Than Mild | B6: 58.595469
A7: Thander Storm | B7: 36
A8: Grand Total | B8: 58.304

Sheet FinD RiderVolBy WeatheStach
A3: Row Labels | B3: Sum of registered | C3: Sum of casual
A4: Mild Cold | B4: 34162 | C4: 3211
A5: More Than Mild | B5: 16568 | C5: 1538
A6: Dark Cloude | B6: 2618 | C6: 171
A7: Thander Storm | B7: 35 | C7: 1
A8: Grand Total | B8: 53383 | C8: 4921

Sheet FinD AVG Rides by temp Band
A3: Row Labels | B3: Average of cnt
A4: Freezing (0-10%) | B4: 29.803922
A5: Very Cold (10-20%) | B5: 50.122995
A6: Cold (20-30%) | B6: 59.995423
A7: Mild (30-40%) | B7: 93.87619
A8: Warm (40-50%) | B8: 59.484848
A9: Grand Total | B9: 58.304

Sheet FinD Total Rides by Time of Day
A3: Row Labels | B3: Average of cnt
A4: Afternoon | B4: 89.646154
A5: Evening | B5: 62.74031
A6: Morning | B6: 67.067194
A7: Night | B7: 8.0393013
A8: Grand Total | B8: 58.304

Sheet FinD Corelation Coeff VS Rides
A3: Row Labels | B3: Sum of Correlation with Rides
A4: Feels-like Temp | B4: 0.17826434
A5: Humidity | B5: -0.2543533
A6: Temperature | B6: 0.22929155
A7: Windspeed | B7: 0.10399668
A8: Grand Total | B8: 0.25719928

Sheet FinD CorrelationTable
A1: Variable | B1: Correlation with Rides
A2: Temperature | B2: =CORREL('Final Dataset'!P:P,'Final Dataset'!J:J) -> 0.22929155
A3: Feels-like Temp | B3: =CORREL('Final Dataset'!P:P,'Final Dataset'!K:K) -> 0.17826434
A4: Humidity | B4: =CORREL('Final Dataset'!P:P,'Final Dataset'!L:L) -> -0.2543533
A5: Windspeed | B5: =CORREL('Final Dataset'!P:P,'Final Dataset'!M:M) -> 0.10399668

Sheet FinD Rash Hour Vs Normal Hour
A3: Row Labels | B3: Average of cnt
A4: Rush Hour | B4: 103.15953
A5: Normal | B5: 42.788694
A6: Grand Total | B6: 58.304

Sheet Fin D Corelation
A1: Date | B1: Cnt | C1: Forecast(Cnt) | D1: Lower Confidence Bound(Cnt) | E1: Upper Confidence Bound(Cnt)
A2: 40544 | B2: 985
A3: 40545 | B3: 801
A4: 40546 | B4: 1349
A5: 40547 | B5: 1562
A6: 40548 | B6: 1600
A7: 40549 | B7: 1606
A8: 40550 | B8: 1510
A9: 40551 | B9: 959
A10: 40552 | B10: 822
A11: 40553 | B11: 1321
A12: 40554 | B12: 1263
A13: 40555 | B13: 1162
... A45: 40587 | B45: 1589
A46: 40588 | B46: 151 | C46: 151 | D46: 151 | E46: 151
A47: 40589 | C47: =_xlfn.FORECAST.ETS(A47,$B$2:$B$46,$A$2:$A$46,1,1) -> 1387.2167 | D47: =C47-_xlfn.FORECAST.ETS.CONFINT(A47,$B$2:$B$46,$A$2:$A$46,0.95,1,1) -> 585.50543 | E47: =C47+_xlfn.FORECAST.ETS.CONFINT(A47,$B$2:$B$46,$A$2:$A$46,0.95,1,1) -> 2188.9281
A48: 40590 | C48: =_xlfn.FORECAST.ETS(A48,$B$2:$B$46,$A$2:$A$46,1,1) -> 1392.5598 | D48: =C48-_xlfn.FORECAST.ETS.CONFINT(A48,$B$2:$B$46,$A$2:$A$46,0.95,1,1) -> 586.7697 | E48: =C48+_xlfn.FORECAST.ETS.CONFINT(A48,$B$2:$B$46,$A$2:$A$46,0.95,1,1) -> 2198.3498
A49: 40591 | C49: =_xlfn.FORECAST.ETS(A49,$B$2:$B$46,$A$2:$A$46,1,1) -> 1397.9028 | D49: =C49-_xlfn.FORECAST.ETS.CONFINT(A49,$B$2:$B$46,$A$2:$A$46,0.95,1,1) -> 587.97397 | E49: =C49+_xlfn.FORECAST.ETS.CONFINT(A49,$B$2:$B$46,$A$2:$A$46,0.95,1,1) -> 2207.8316
A50: 40592 | C50: =_xlfn.FORECAST.ETS(A50,$B$2:$B$46,$A$2:$A$46,1,1) -> 1403.2458 | D50: =C50-_xlfn.FORECAST.ETS.CONFINT(A50,$B$2:$B$46,$A$2:$A$46,0.95,1,1) -> 589.11835 | E50: =C50+_xlfn.FORECAST.ETS.CONFINT(A50,$B$2:$B$46,$A$2:$A$46,0.95,1,1) -> 2217.3733
A51: 40593 | C51: =_xlfn.FORECAST.ETS(A51,$B$2:$B$46,$A$2:$A$46,1,1) -> 1408.5889 | D51: =C51-_xlfn.FORECAST.ETS.CONFINT(A51,$B$2:$B$46,$A$2:$A$46,0.95,1,1) -> 590.20299 | E51: =C51+_xlfn.FORECAST.ETS.CONFINT(A51,$B$2:$B$46,$A$2:$A$46,0.95,1,1) -> 2226.9747
A52: 40594 | C52: =_xlfn.FORECAST.ETS(A52,$B$2:$B$46,$A$2:$A$46,1,1) -> 1413.9319 | D52: =C52-_xlfn.FORECAST.ETS.CONFINT(A52,$B$2:$B$46,$A$2:$A$46,0.95,1,1) -> 591.22802 | E52: =C52+_xlfn.FORECAST.ETS.CONFINT(A52,$B$2:$B$46,$A$2:$A$46,0.95,1,1) -> 2236.6358
A53: 40595 | C53: =_xlfn.FORECAST.ETS(A53,$B$2:$B$46,$A$2:$A$46,1,1) -> 1419.2749 | D53: =C53-_xlfn.FORECAST.ETS.CONFINT(A53,$B$2:$B$46,$A$2:$A$46,0.95,1,1) -> 592.19361 | E53: =C53+_xlfn.FORECAST.ETS.CONFINT(A53,$B$2:$B$46,$A$2:$A$46,0.95,1,1) -> 2246.3562

Sheet Final Dataset
A1: instant | B1: dteday | C1: season | D1: yr | E1: mnth | F1: hr | G1: holiday | H1: weekday | I1: weathersit | J1: temp | K1: atemp | L1: hum | M1: windspeed | N1: casual | O1: registered | P1: cnt | Q1: Weekday_By Name | R1: Weather | S1: Rash Hour | T1: Demand Category | U1: Times of Day | V1: Temp Band | W1: Detection(surprisingly high or low)
A2: 1 | B2: 40544 | C2: 1 | D2: 0 | E2: 1 | F2: 0 | G2: FALSE | H2: 6 | I2: 1 | J2: 0.24 | K2: 0.2879 | L2: 0.81 | M2: 0 | N2: 3 | O2: 13 | P2: 16 | Q2: Sunday | R2: Mild Cold | S2: =IF(OR(AND(F2>=7,F2<=9),AND(F2>=17,F2<=19)),"Rush Hour","Normal") -> Normal | T2: =IF(P2>150,"High",IF(P2>50,"Medium","Low")) -> Low | U2: =IF(F2<6,"Night", IF(F2<12,"Morning", IF(F2<18,"Afternoon","Evening"))) -> Night | V2: =IF(J2<0.1,"Freezing (0-10%)", IF(J2<0.2,"Very Cold (10-20%)", IF(J2<0.3,"Cold (20-30%)", IF(J2<0.4,"Mild (30-40%)", IF(J2<0.5,"Warm (40-50%)", "Hot (50%+)"))))) -> Cold (20-30%) | W2: =IF(ABS(P2-AVERAGE($P$2:$P$1001))>2*STDEV($P$2:$P$1001),IF(P2>AVERAGE($P$2:$P$1001),"⬆ Spike","⬇ Drop"), "Normal") -> Normal
A3: 2 | B3: 40544 | C3: 1 | D3: 0 | E3: 1 | F3: 1 | G3: FALSE | H3: 6 | I3: 1 | J3: 0.22 | K3: 0.2727 | L3: 0.8 | M3: 0 | N3: 8 | O3: 32 | P3: 40 | Q3: Sunday | R3: Mild Cold | S3: =IF(OR(AND(F3>=7,F3<=9),AND(F3>=17,F3<=19)),"Rush Hour","Normal") -> Normal | T3: =IF(P3>150,"High",IF(P3>50,"Medium","Low")) -> Low | U3: =IF(F3<6,"Night", IF(F3<12,"Morning", IF(F3<18,"Afternoon","Evening"))) -> Night | V3: =IF(J3<0.1,"Freezing (0-10%)", IF(J3<0.2,"Very Cold (10-20%)", IF(J3<0.3,"Cold (20-30%)", IF(J3<0.4,"Mild (30-40%)", IF(J3<0.5,"Warm (40-50%)", "Hot (50%+)"))))) -> Cold (20-30%) | W3: =IF(ABS(P3-AVERAGE($P$2:$P$1001))>2*STDEV($P$2:$P$1001),IF(P3>AVERAGE($P$2:$P$1001),"⬆ Spike","⬇ Drop"), "Normal") -> Normal | X3: Summary Statistics
A4: 3 | B4: 40544 | C4: 1 | D4: 0 | E4: 1 | F4: 2 | G4: FALSE | H4: 6 | I4: 1 | J4: 0.22 | K4: 0.2727 | L4: 0.8 | M4: 0 | N4: 5 | O4: 27 | P4: 32 | Q4: Sunday | R4: Mild Cold | S4: =IF(OR(AND(F4>=7,F4<=9),AND(F4>=17,F4<=19)),"Rush Hour","Normal") -> Normal | T4: =IF(P4>150,"High",IF(P4>50,"Medium","Low")) -> Low | U4: =IF(F4<6,"Night", IF(F4<12,"Morning", IF(F4<18,"Afternoon","Evening"))) -> Night | V4: =IF(J4<0.1,"Freezing (0-10%)", IF(J4<0.2,"Very Cold (10-20%)", IF(J4<0.3,"Cold (20-30%)", IF(J4<0.4,"Mild (30-40%)", IF(J4<0.5,"Warm (40-50%)", "Hot (50%+)"))))) -> Cold (20-30%) | W4: =IF(ABS(P4-AVERAGE($P$2:$P$1001))>2*STDEV($P$2:$P$1001),IF(P4>AVERAGE($P$2:$P$1001),"⬆ Spike","⬇ Drop"), "Normal") -> Normal | X4: Total rides | Z4: =SUM(P:P) -> 58304
A5: 4 | B5: 40544 | C5: 1 | D5: 0 | E5: 1 | F5: 3 | G5: FALSE | H5: 6 | I5: 1 | J5: 0.24 | K5: 0.2879 | L5: 0.75 | M5: 0 | N5: 3 | O5: 10 | P5: 13 | Q5: Sunday | R5: Mild Cold | S5: =IF(OR(AND(F5>=7,F5<=9),AND(F5>=17,F5<=19)),"Rush Hour","Normal") -> Normal | T5: =IF(P5>150,"High",IF(P5>50,"Medium","Low")) -> Low | U5: =IF(F5<6,"Night", IF(F5<12,"Morning", IF(F5<18,"Afternoon","Evening"))) -> Night | V5: =IF(J5<0.1,"Freezing (0-10%)", IF(J5<0.2,"Very Cold (10-20%)", IF(J5<0.3,"Cold (20-30%)", IF(J5<0.4,"Mild (30-40%)", IF(J5<0.5,"Warm (40-50%)", "Hot (50%+)"))))) -> Cold (20-30%) | W5: =IF(ABS(P5-AVERAGE($P$2:$P$1001))>2*STDEV($P$2:$P$1001),IF(P5>AVERAGE($P$2:$P$1001),"⬆ Spike","⬇ Drop"), "Normal") -> Normal | X5: Average rides per hour | Z5: =AVERAGE(P:P) -> 58.304
A6: 5 | B6: 40544 | C6: 1 | D6: 0 | E6: 1 | F6: 4 | G6: FALSE | H6: 6 | I6: 1 | J6: 0.24 | K6: 0.2879 | L6: 0.75 | M6: 0 | N6: 0 | O6: 1 | P6: 1 | Q6: Sunday | R6: Mild Cold | S6: =IF(OR(AND(F6>=7,F6<=9),AND(F6>=17,F6<=19)),"Rush Hour","Normal") -> Normal | T6: =IF(P6>150,"High",IF(P6>50,"Medium","Low")) -> Low | U6: =IF(F6<6,"Night", IF(F6<12,"Morning", IF(F6<18,"Afternoon","Evening"))) -> Night | V6: =IF(J6<0.1,"Freezing (0-10%)", IF(J6<0.2,"Very Cold (10-20%)", IF(J6<0.3,"Cold (20-30%)", IF(J6<0.4,"Mild (30-40%)", IF(J6<0.5,"Warm (40-50%)", "Hot (50%+)"))))) -> Cold (20-30%) | W6: =IF(ABS(P6-AVERAGE($P$2:$P$1001))>2*STDEV($P$2:$P$1001),IF(P6>AVERAGE($P$2:$P$1001),"⬆ Spike","⬇ Drop"), "Normal") -> Normal | X6: Peak single hour demand | Z6: =MAX(P:P) -> 249
A7: 6 | B7: 40544 | C7: 1 | D7: 0 | E7: 1 | F7: 5 | G7: FALSE | H7: 6 | I7: 2 | J7: 0.24 | K7: 0.2576 | L7: 0.75 | M7: 0.0896 | N7: 0 | O7: 1 | P7: 1 | Q7: Sunday | R7: More Than Mild | S7: =IF(OR(AND(F7>=7,F7<=9),AND(F7>=17,F7<=19)),"Rush Hour","Normal") -> Normal | T7: =IF(P7>150,"High",IF(P7>50,"Medium","Low")) -> Low | U7: =IF(F7<6,"Night", IF(F7<12,"Morning", IF(F7<18,"Afternoon","Evening"))) -> Night | V7: =IF(J7<0.1,"Freezing (0-10%)", IF(J7<0.2,"Very Cold (10-20%)", IF(J7<0.3,"Cold (20-30%)", IF(J7<0.4,"Mild (30-40%)", IF(J7<0.5,"Warm (40-50%)", "Hot (50%+)"))))) -> Cold (20-30%) | W7: =IF(ABS(P7-AVERAGE($P$2:$P$1001))>2*STDEV($P$2:$P$1001),IF(P7>AVERAGE($P$2:$P$1001),"⬆ Spike","⬇ Drop"), "Normal") -> Normal | X7: Lowest single hour demand | Z7: =MIN(P:P) -> 1
A8: 7 | B8: 40544 | C8: 1 | D8: 0 | E8: 1 | F8: 6 | G8: FALSE | H8: 6 | I8: 1 | J8: 0.22 | K8: 0.2727 | L8: 0.8 | M8: 0 | N8: 2 | O8: 0 | P8: 2 | Q8: Sunday | R8: Mild Cold | S8: =IF(OR(AND(F8>=7,F8<=9),AND(F8>=17,F8<=19)),"Rush Hour","Normal") -> Normal | T8: =IF(P8>150,"High",IF(P8>50,"Medium","Low")) -> Low | U8: =IF(F8<6,"Night", IF(F8<12,"Morning", IF(F8<18,"Afternoon","Evening"))) -> Morning | V8: =IF(J8<0.1,"Freezing (0-10%)", IF(J8<0.2,"Very Cold (10-20%)", IF(J8<0.3,"Cold (20-30%)", IF(J8<0.4,"Mild (30-40%)", IF(J8<0.5,"Warm (40-50%)", "Hot (50%+)"))))) -> Cold (20-30%) | W8: =IF(ABS(P8-AVERAGE($P$2:$P$1001))>2*STDEV($P$2:$P$1001),IF(P8>AVERAGE($P$2:$P$1001),"⬆ Spike","⬇ Drop"), "Normal") -> Normal | X8: Demand variability | Z8: =STDEV(P:P) -> 50.985558
A9: 8 | B9: 40544 | C9: 1 | D9: 0 | E9: 1 | F9: 7 | G9: FALSE | H9: 6 | I9: 1 | J9: 0.2 | K9: 0.2576 | L9: 0.86 | M9: 0 | N9: 1 | O9: 2 | P9: 3 | Q9: Sunday | R9: Mild Cold | S9: =IF(OR(AND(F9>=7,F9<=9),AND(F9>=17,F9<=19)),"Rush Hour","Normal") -> Rush Hour | T9: =IF(P9>150,"High",IF(P9>50,"Medium","Low")) -> Low | U9: =IF(F9<6,"Night", IF(F9<12,"Morning", IF(F9<18,"Afternoon","Evening"))) -> Morning | V9: =IF(J9<0.1,"Freezing (0-10%)", IF(J9<0.2,"Very Cold (10-20%)", IF(J9<0.3,"Cold (20-30%)", IF(J9<0.4,"Mild (30-40%)", IF(J9<0.5,"Warm (40-50%)", "Hot (50%+)"))))) -> Cold (20-30%) | W9: =IF(ABS(P9-AVERAGE($P$2:$P$1001))>2*STDEV($P$2:$P$1001),IF(P9>AVERAGE($P$2:$P$1001),"⬆ Spike","⬇ Drop"), "Normal") -> Normal | X9: Total hourly records | Z9: =COUNT(P:P) -> 1000
A10: 9 | B10: 40544 | C10: 1 | D10: 0 | E10: 1 | F10: 8 | G10: FALSE | H10: 6 | I10: 1 | J10: 0.24 | K10: 0.2879 | L10: 0.75 | M10: 0 | N10: 1 | O10: 7 | P10: 8 | Q10: Sunday | R10: Mild Cold | S10: =IF(OR(AND(F10>=7,F10<=9),AND(F10>=17,F10<=19)),"Rush Hour","Normal") -> Rush Hour | T10: =IF(P10>150,"High",IF(P10>50,"Medium","Low")) -> Low | U10: =IF(F10<6,"Night", IF(F10<12,"Morning", IF(F10<18,"Afternoon","Evening"))) -> Morning | V10: =IF(J10<0.1,"Freezing (0-10%)", IF(J10<0.2,"Very Cold (10-20%)", IF(J10<0.3,"Cold (20-30%)", IF(J10<0.4,"Mild (30-40%)", IF(J10<0.5,"Warm (40-50%)", "Hot (50%+)"))))) -> Cold (20-30%) | W10: =IF(ABS(P10-AVERAGE($P$2:$P$1001))>2*STDEV($P$2:$P$1001),IF(P10>AVERAGE($P$2:$P$1001),"⬆ Spike","⬇ Drop"), "Normal") -> Normal
A11: 10 | B11: 40544 | C11: 1 | D11: 0 | E11: 1 | F11: 9 | G11: FALSE | H11: 6 | I11: 1 | J11: 0.32 | K11: 0.3485 | L11: 0.76 | M11: 0 | N11: 8 | O11: 6 | P11: 14 | Q11: Sunday | R11: Mild Cold | S11: =IF(OR(AND(F11>=7,F11<=9),AND(F11>=17,F11<=19)),"Rush Hour","Normal") -> Rush Hour | T11: =IF(P11>150,"High",IF(P11>50,"Medium","Low")) -> Low | U11: =IF(F11<6,"Night", IF(F11<12,"Morning", IF(F11<18,"Afternoon","Evening"))) -> Morning | V11: =IF(J11<0.1,"Freezing (0-10%)", IF(J11<0.2,"Very Cold (10-20%)", IF(J11<0.3,"Cold (20-30%)", IF(J11<0.4,"Mild (30-40%)", IF(J11<0.5,"Warm (40-50%)", "Hot (50%+)"))))) -> Mild (30-40%) | W11: =IF(ABS(P11-AVERAGE($P$2:$P$1001))>2*STDEV($P$2:$P$1001),IF(P11>AVERAGE($P$2:$P$1001),"⬆ Spike","⬇ Drop"), "Normal") -> Normal | X11: User type breakdown:
A12: 11 | B12: 40544 | C12: 1 | D12: 0 | E12: 1 | F12: 10 | G12: FALSE | H12: 6 | I12: 1 | J12: 0.38 | K12: 0.3939 | L12: 0.76 | M12: 0.2537 | N12: 12 | O12: 24 | P12: 36 | Q12: Sunday | R12: Mild Cold | S12: =IF(OR(AND(F12>=7,F12<=9),AND(F12>=17,F12<=19)),"Rush Hour","Normal") -> Normal | T12: =IF(P12>150,"High",IF(P12>50,"Medium","Low")) -> Low | U12: =IF(F12<6,"Night", IF(F12<12,"Morning", IF(F12<18,"Afternoon","Evening"))) -> Morning | V12: =IF(J12<0.1,"Freezing (0-10%)", IF(J12<0.2,"Very Cold (10-20%)", IF(J12<0.3,"Cold (20-30%)", IF(J12<0.4,"Mild (30-40%)", IF(J12<0.5,"Warm (40-50%)", "Hot (50%+)"))))) -> Mild (30-40%) | W12: =IF(ABS(P12-AVERAGE($P$2:$P$1001))>2*STDEV($P$2:$P$1001),IF(P12>AVERAGE($P$2:$P$1001),"⬆ Spike","⬇ Drop"), "Normal") -> Normal | X12: Total casual rides | Z12: =SUM(N:N) -> 4921
A13: 12 | B13: 40544 | C13: 1 | D13: 0 | E13: 1 | F13: 11 | G13: FALSE | H13: 6 | I13: 1 | J13: 0.36 | K13: 0.3333 | L13: 0.81 | M13: 0.2836 | N13: 26 | O13: 30 | P13: 56 | Q13: Sunday | R13: Mild Cold | S13: =IF(OR(AND(F13>=7,F13<=9),AND(F13>=17,F13<=19)),"Rush Hour","Normal") -> Normal | T13: =IF(P13>150,"High",IF(P13>50,"Medium","Low")) -> Medium | U13: =IF(F13<6,"Night", IF(F13<12,"Morning", IF(F13<18,"Afternoon","Evening"))) -> Morning | V13: =IF(J13<0.1,"Freezing (0-10%)", IF(J13<0.2,"Very Cold (10-20%)", IF(J13<0.3,"Cold (20-30%)", IF(J13<0.4,"Mild (30-40%)", IF(J13<0.5,"Warm (40-50%)", "Hot (50%+)"))))) -> Mild (30-40%) | W13: =IF(ABS(P13-AVERAGE($P$2:$P$1001))>2*STDEV($P$2:$P$1001),IF(P13>AVERAGE($P$2:$P$1001),"⬆ Spike","⬇ Drop"), "Normal") -> Normal | X13: Total registered rides | Z13: =SUM(O:O) -> 53383
A14: 13 | B14: 40544 | C14: 1 | D14: 0 | E14: 1 | F14: 12 | G14: FALSE | H14: 6 | I14: 1 | J14: 0.42 | K14: 0.4242 | L14: 0.77 | M14: 0.2836 | N14: 29 | O14: 55 | P14: 84 | Q14: Sunday | R14: Mild Cold | S14: =IF(OR(AND(F14>=7,F14<=9),AND(F14>=17,F14<=19)),"Rush Hour","Normal") -> Normal | T14: =IF(P14>150,"High",IF(P14>50,"Medium","Low")) -> Medium | U14: =IF(F14<6,"Night", IF(F14<12,"Morning", IF(F14<18,"Afternoon","Evening"))) -> Afternoon | V14: =IF(J14<0.1,"Freezing (0-10%)", IF(J14<0.2,"Very Cold (10-20%)", IF(J14<0.3,"Cold (20-30%)", IF(J14<0.4,"Mild (30-40%)", IF(J14<0.5,"Warm (40-50%)", "Hot (50%+)"))))) -> Warm (40-50%) | W14: =IF(ABS(P14-AVERAGE($P$2:$P$1001))>2*STDEV($P$2:$P$1001),IF(P14>AVERAGE($P$2:$P$1001),"⬆ Spike","⬇ Drop"), "Normal") -> Normal | X14: Casual % | Z14: =SUM(N:N)/SUM(P:P) -> 0.084402442
A15: 14 | B15: 40544 | C15: 1 | D15: 0 | E15: 1 | F15: 13 | G15: FALSE | H15: 6 | I15: 2 | J15: 0.46 | K15: 0.4545 | L15: 0.72 | M15: 0.2985 | N15: 47 | O15: 47 | P15: 94 | Q15: Sunday | R15: More Than Mild | S15: =IF(OR(AND(F15>=7,F15<=9),AND(F15>=17,F15<=19)),"Rush Hour","Normal") -> Normal | T15: =IF(P15>150,"High",IF(P15>50,"Medium","Low")) -> Medium | U15: =IF(F15<6,"Night", IF(F15<12,"Morning", IF(F15<18,"Afternoon","Evening"))) -> Afternoon | V15: =IF(J15<0.1,"Freezing (0-10%)", IF(J15<0.2,"Very Cold (10-20%)", IF(J15<0.3,"Cold (20-30%)", IF(J15<0.4,"Mild (30-40%)", IF(J15<0.5,"Warm (40-50%)", "Hot (50%+)"))))) -> Warm (40-50%) | W15: =IF(ABS(P15-AVERAGE($P$2:$P$1001))>2*STDEV($P$2:$P$1001),IF(P15>AVERAGE($P$2:$P$1001),"⬆ Spike","⬇ Drop"), "Normal") -> Normal | X15: Registered % | Z15: =SUM(O:O)/SUM(P:P) -> 0.91559756
A16: 15 | B16: 40544 | C16: 1 | D16: 0 | E16: 1 | F16: 14 | G16: FALSE | H16: 6 | I16: 2 | J16: 0.46 | K16: 0.4545 | L16: 0.72 | M16: 0.2836 | N16: 35 | O16: 71 | P16: 106 | Q16: Sunday | R16: More Than Mild | S16: =IF(OR(AND(F16>=7,F16<=9),AND(F16>=17,F16<=19)),"Rush Hour","Normal") -> Normal | T16: =IF(P16>150,"High",IF(P16>50,"Medium","Low")) -> Medium | U16: =IF(F16<6,"Night", IF(F16<12,"Morning", IF(F16<18,"Afternoon","Evening"))) -> Afternoon | V16: =IF(J16<0.1,"Freezing (0-10%)", IF(J16<0.2,"Very Cold (10-20%)", IF(J16<0.3,"Cold (20-30%)", IF(J16<0.4,"Mild (30-40%)", IF(J16<0.5,"Warm (40-50%)", "Hot (50%+)"))))) -> Warm (40-50%) | W16: =IF(ABS(P16-AVERAGE($P$2:$P$1001))>2*STDEV($P$2:$P$1001),IF(P16>AVERAGE($P$2:$P$1001),"⬆ Spike","⬇ Drop"), "Normal") -> Normal
A17: 16 | B17: 40544 | C17: 1 | D17: 0 | E17: 1 | F17: 15 | G17: FALSE | H17: 6 | I17: 2 | J17: 0.44 | K17: 0.4394 | L17: 0.77 | M17: 0.2985 | N17: 40 | O17: 70 | P17: 110 | Q17: Sunday | R17: More Than Mild | S17: =IF(OR(AND(F17>=7,F17<=9),AND(F17>=17,F17<=19)),"Rush Hour","Normal") -> Normal | T17: =IF(P17>150,"High",IF(P17>50,"Medium","Low")) -> Medium | U17: =IF(F17<6,"Night", IF(F17<12,"Morning", IF(F17<18,"Afternoon","Evening"))) -> Afternoon | V17: =IF(J17<0.1,"Freezing (0-10%)", IF(J17<0.2,"Very Cold (10-20%)", IF(J17<0.3,"Cold (20-30%)", IF(J17<0.4,"Mild (30-40%)", IF(J17<0.5,"Warm (40-50%)", "Hot (50%+)"))))) -> Warm (40-50%) | W17: =IF(ABS(P17-AVERAGE($P$2:$P$1001))>2*STDEV($P$2:$P$1001),IF(P17>AVERAGE($P$2:$P$1001),"⬆ Spike","⬇ Drop"), "Normal") -> Normal | X17: Weather stats:
A18: 17 | B18: 40544 | C18: 1 | D18: 0 | E18: 1 | F18: 16 | G18: FALSE | H18: 6 | I18: 2 | J18: 0.42 | K18: 0.4242 | L18: 0.82 | M18: 0.2985 | N18: 41 | O18: 52 | P18: 93 | Q18: Sunday | R18: More Than Mild | S18: =IF(OR(AND(F18>=7,F18<=9),AND(F18>=17,F18<=19)),"Rush Hour","Normal") -> Normal | T18: =IF(P18>150,"High",IF(P18>50,"Medium","Low")) -> Medium | U18: =IF(F18<6,"Night", IF(F18<12,"Morning", IF(F18<18,"Afternoon","Evening"))) -> Afternoon | V18: =IF(J18<0.1,"Freezing (0-10%)", IF(J18<0.2,"Very Cold (10-20%)", IF(J18<0.3,"Cold (20-30%)", IF(J18<0.4,"Mild (30-40%)", IF(J18<0.5,"Warm (40-50%)", "Hot (50%+)"))))) -> Warm (40-50%) | W18: =IF(ABS(P18-AVERAGE($P$2:$P$1001))>2*STDEV($P$2:$P$1001),IF(P18>AVERAGE($P$2:$P$1001),"⬆ Spike","⬇ Drop"), "Normal") -> Normal | X18: Hours with Mild/Cold weather | Z18: =COUNTIF(I:I, 1) -> 606
A19: 18 | B19: 40544 | C19: 1 | D19: 0 | E19: 1 | F19: 17 | G19: FALSE | H19: 6 | I19: 2 | J19: 0.44 | K19: 0.3485 | L19: 0.82 | M19: 0.2836 | N19: 15 | O19: 52 | P19: 67 | Q19: Sunday | R19: More Than Mild | S19: =IF(OR(AND(F19>=7,F19<=9),AND(F19>=17,F19<=19)),"Rush Hour","Normal") -> Rush Hour | T19: =IF(P19>150,"High",IF(P19>50,"Medium","Low")) -> Medium | U19: =IF(F19<6,"Night", IF(F19<12,"Morning", IF(F19<18,"Afternoon","Evening"))) -> Afternoon | V19: =IF(J19<0.1,"Freezing (0-10%)", IF(J19<0.2,"Very Cold (10-20%)", IF(J19<0.3,"Cold (20-30%)", IF(J19<0.4,"Mild (30-40%)", IF(J19<0.5,"Warm (40-50%)", "Hot (50%+)"))))) -> Warm (40-50%) | W19: =IF(ABS(P19-AVERAGE($P$2:$P$1001))>2*STDEV($P$2:$P$1001),IF(P19>AVERAGE($P$2:$P$1001),"⬆ Spike","⬇ Drop"), "Normal") -> Normal | X19: Hours with More Than Mild | Z19: =COUNTIF(I:I, 2) -> 309
A20: 19 | B20: 40544 | C20: 1 | D20: 0 | E20: 1 | F20: 18 | G20: FALSE | H20: 6 | I20: 3 | J20: 0.42 | K20: 0.4242 | L20: 0.88 | M20: 0.2537 | N20: 9 | O20: 26 | P20: 35 | Q20: Sunday | R20: Dark Cloude | S20: =IF(OR(AND(F20>=7,F20<=9),AND(F20>=17,F20<=19)),"Rush Hour","Normal") -> Rush Hour | T20: =IF(P20>150,"High",IF(P20>50,"Medium","Low")) -> Low | U20: =IF(F20<6,"Night", IF(F20<12,"Morning", IF(F20<18,"Afternoon","Evening"))) -> Evening | V20: =IF(J20<0.1,"Freezing (0-10%)", IF(J20<0.2,"Very Cold (10-20%)", IF(J20<0.3,"Cold (20-30%)", IF(J20<0.4,"Mild (30-40%)", IF(J20<0.5,"Warm (40-50%)", "Hot (50%+)"))))) -> Warm (40-50%) | W20: =IF(ABS(P20-AVERAGE($P$2:$P$1001))>2*STDEV($P$2:$P$1001),IF(P20>AVERAGE($P$2:$P$1001),"⬆ Spike","⬇ Drop"), "Normal") -> Normal | X20: Hours with Dark Cloud | Z20: =COUNTIF(I:I, 3) -> 84
A21: 20 | B21: 40544 | C21: 1 | D21: 0 | E21: 1 | F21: 19 | G21: FALSE | H21: 6 | I21: 3 | J21: 0.42 | K21: 0.4242 | L21: 0.88 | M21: 0.2537 | N21: 6 | O21: 31 | P21: 37 | Q21: Sunday | R21: Dark Cloude | S21: =IF(OR(AND(F21>=7,F21<=9),AND(F21>=17,F21<=19)),"Rush Hour","Normal") -> Rush Hour | T21: =IF(P21>150,"High",IF(P21>50,"Medium","Low")) -> Low | U21: =IF(F21<6,"Night", IF(F21<12,"Morning", IF(F21<18,"Afternoon","Evening"))) -> Evening | V21: =IF(J21<0.1,"Freezing (0-10%)", IF(J21<0.2,"Very Cold (10-20%)", IF(J21<0.3,"Cold (20-30%)", IF(J21<0.4,"Mild (30-40%)", IF(J21<0.5,"Warm (40-50%)", "Hot (50%+)"))))) -> Warm (40-50%) | W21: =IF(ABS(P21-AVERAGE($P$2:$P$1001))>2*STDEV($P$2:$P$1001),IF(P21>AVERAGE($P$2:$P$1001),"⬆ Spike","⬇ Drop"), "Normal") -> Normal | X21: Hours with Thunder Storm | Z21: =COUNTIF(I:I, 4) -> 1
A22: 21 | B22: 40544 | C22: 1 | D22: 0 | E22: 1 | F22: 20 | G22: FALSE | H22: 6 | I22: 2 | J22: 0.4 | K22: 0.4091 | L22: 0.87 | M22: 0.2537 | N22: 11 | O22: 25 | P22: 36 | Q22: Sunday | R22: More Than Mild | S22: =IF(OR(AND(F22>=7,F22<=9),AND(F22>=17,F22<=19)),"Rush Hour","Normal") -> Normal | T22: =IF(P22>150,"High",IF(P22>50,"Medium","Low")) -> Low | U22: =IF(F22<6,"Night", IF(F22<12,"Morning", IF(F22<18,"Afternoon","Evening"))) -> Evening | V22: =IF(J22<0.1,"Freezing (0-10%)", IF(J22<0.2,"Very Cold (10-20%)", IF(J22<0.3,"Cold (20-30%)", IF(J22<0.4,"Mild (30-40%)", IF(J22<0.5,"Warm (40-50%)", "Hot (50%+)"))))) -> Warm (40-50%) | W22: =IF(ABS(P22-AVERAGE($P$2:$P$1001))>2*STDEV($P$2:$P$1001),IF(P22>AVERAGE($P$2:$P$1001),"⬆ Spike","⬇ Drop"), "Normal") -> Normal | X22: Avg rides in Mild/Cold | Z22: =AVERAGEIF(I:I,1,P:P) -> 61.671617
A23: 22 | B23: 40544 | C23: 1 | D23: 0 | E23: 1 | F23: 21 | G23: FALSE | H23: 6 | I23: 2 | J23: 0.4 | K23: 0.4091 | L23: 0.87 | M23: 0.194 | N23: 3 | O23: 31 | P23: 34 | Q23: Sunday | R23: More Than Mild | S23: =IF(OR(AND(F23>=7,F23<=9),AND(F23>=17,F23<=19)),"Rush Hour","Normal") -> Normal | T23: =IF(P23>150,"High",IF(P23>50,"Medium","Low")) -> Low | U23: =IF(F23<6,"Night", IF(F23<12,"Morning", IF(F23<18,"Afternoon","Evening"))) -> Evening | V23: =IF(J23<0.1,"Freezing (0-10%)", IF(J23<0.2,"Very Cold (10-20%)", IF(J23<0.3,"Cold (20-30%)", IF(J23<0.4,"Mild (30-40%)", IF(J23<0.5,"Warm (40-50%)", "Hot (50%+)"))))) -> Warm (40-50%) | W23: =IF(ABS(P23-AVERAGE($P$2:$P$1001))>2*STDEV($P$2:$P$1001),IF(P23>AVERAGE($P$2:$P$1001),"⬆ Spike","⬇ Drop"), "Normal") -> Normal | X23: Avg rides in More Than Mild | Z23: =AVERAGEIF(I:I,2,P:P) -> 58.595469
A24: 23 | B24: 40544 | C24: 1 | D24: 0 | E24: 1 | F24: 22 | G24: FALSE | H24: 6 | I24: 2 | J24: 0.4 | K24: 0.4091 | L24: 0.94 | M24: 0.2239 | N24: 11 | O24: 17 | P24: 28 | Q24: Sunday | R24: More Than Mild | S24: =IF(OR(AND(F24>=7,F24<=9),AND(F24>=17,F24<=19)),"Rush Hour","Normal") -> Normal | T24: =IF(P24>150,"High",IF(P24>50,"Medium","Low")) -> Low | U24: =IF(F24<6,"Night", IF(F24<12,"Morning", IF(F24<18,"Afternoon","Evening"))) -> Evening | V24: =IF(J24<0.1,"Freezing (0-10%)", IF(J24<0.2,"Very Cold (10-20%)", IF(J24<0.3,"Cold (20-30%)", IF(J24<0.4,"Mild (30-40%)", IF(J24<0.5,"Warm (40-50%)", "Hot (50%+)"))))) -> Warm (40-50%) | W24: =IF(ABS(P24-AVERAGE($P$2:$P$1001))>2*STDEV($P$2:$P$1001),IF(P24>AVERAGE($P$2:$P$1001),"⬆ Spike","⬇ Drop"), "Normal") -> Normal | X24: Avg rides in Dark Cloud | Z24: =AVERAGEIF(I:I,3,P:P) -> 33.202381
A25: 24 | B25: 40544 | C25: 1 | D25: 0 | E25: 1 | F25: 23 | G25: FALSE | H25: 6 | I25: 2 | J25: 0.46 | K25: 0.4394 | L25: 0.88 | M25: 0.2985 | N25: 15 | O25: 24 | P25: 39 | Q25: Sunday | R25: More Than Mild | S25: =IF(OR(AND(F25>=7,F25<=9),AND(F25>=17,F25<=19)),"Rush Hour","Normal") -> Normal | T25: =IF(P25>150,"High",IF(P25>50,"Medium","Low")) -> Low | U25: =IF(F25<6,"Night", IF(F25<12,"Morning", IF(F25<18,"Afternoon","Evening"))) -> Evening | V25: =IF(J25<0.1,"Freezing (0-10%)", IF(J25<0.2,"Very Cold (10-20%)", IF(J25<0.3,"Cold (20-30%)", IF(J25<0.4,"Mild (30-40%)", IF(J25<0.5,"Warm (40-50%)", "Hot (50%+)"))))) -> Warm (40-50%) | W25: =IF(ABS(P25-AVERAGE($P$2:$P$1001))>2*STDEV($P$2:$P$1001),IF(P25>AVERAGE($P$2:$P$1001),"⬆ Spike","⬇ Drop"), "Normal") -> Normal
A26: 25 | B26: 40545 | C26: 1 | D26: 0 | E26: 1 | F26: 0 | G26: FALSE | H26: 0 | I26: 2 | J26: 0.46 | K26: 0.4545 | L26: 0.88 | M26: 0.2985 | N26: 4 | O26: 13 | P26: 17 | Q26: Monday | R26: More Than Mild | S26: =IF(OR(AND(F26>=7,F26<=9),AND(F26>=17,F26<=19)),"Rush Hour","Normal") -> Normal | T26: =IF(P26>150,"High",IF(P26>50,"Medium","Low")) -> Low | U26: =IF(F26<6,"Night", IF(F26<12,"Morning", IF(F26<18,"Afternoon","Evening"))) -> Night | V26: =IF(J26<0.1,"Freezing (0-10%)", IF(J26<0.2,"Very Cold (10-20%)", IF(J26<0.3,"Cold (20-30%)", IF(J26<0.4,"Mild (30-40%)", IF(J26<0.5,"Warm (40-50%)", "Hot (50%+)"))))) -> Warm (40-50%) | W26: =IF(ABS(P26-AVERAGE($P$2:$P$1001))>2*STDEV($P$2:$P$1001),IF(P26>AVERAGE($P$2:$P$1001),"⬆ Spike","⬇ Drop"), "Normal") -> Normal | X26: Correlation analysis:
A27: 26 | B27: 40545 | C27: 1 | D27: 0 | E27: 1 | F27: 1 | G27: FALSE | H27: 0 | I27: 2 | J27: 0.44 | K27: 0.4394 | L27: 0.94 | M27: 0.2537 | N27: 1 | O27: 16 | P27: 17 | Q27: Monday | R27: More Than Mild | S27: =IF(OR(AND(F27>=7,F27<=9),AND(F27>=17,F27<=19)),"Rush Hour","Normal") -> Normal | T27: =IF(P27>150,"High",IF(P27>50,"Medium","Low")) -> Low | U27: =IF(F27<6,"Night", IF(F27<12,"Morning", IF(F27<18,"Afternoon","Evening"))) -> Night | V27: =IF(J27<0.1,"Freezing (0-10%)", IF(J27<0.2,"Very Cold (10-20%)", IF(J27<0.3,"Cold (20-30%)", IF(J27<0.4,"Mild (30-40%)", IF(J27<0.5,"Warm (40-50%)", "Hot (50%+)"))))) -> Warm (40-50%) | W27: =IF(ABS(P27-AVERAGE($P$2:$P$1001))>2*STDEV($P$2:$P$1001),IF(P27>AVERAGE($P$2:$P$1001),"⬆ Spike","⬇ Drop"), "Normal") -> Normal | X27: Temp vs Cnt | Z27: =CORREL(J:J,P:P) -> 0.22929155
A28: 27 | B28: 40545 | C28: 1 | D28: 0 | E28: 1 | F28: 2 | G28: FALSE | H28: 0 | I28: 2 | J28: 0.42 | K28: 0.4242 | L28: 1 | M28: 0.2836 | N28: 1 | O28: 8 | P28: 9 | Q28: Monday | R28: More Than Mild | S28: =IF(OR(AND(F28>=7,F28<=9),AND(F28>=17,F28<=19)),"Rush Hour","Normal") -> Normal | T28: =IF(P28>150,"High",IF(P28>50,"Medium","Low")) -> Low | U28: =IF(F28<6,"Night", IF(F28<12,"Morning", IF(F28<18,"Afternoon","Evening"))) -> Night | V28: =IF(J28<0.1,"Freezing (0-10%)", IF(J28<0.2,"Very Cold (10-20%)", IF(J28<0.3,"Cold (20-30%)", IF(J28<0.4,"Mild (30-40%)", IF(J28<0.5,"Warm (40-50%)", "Hot (50%+)"))))) -> Warm (40-50%) | W28: =IF(ABS(P28-AVERAGE($P$2:$P$1001))>2*STDEV($P$2:$P$1001),IF(P28>AVERAGE($P$2:$P$1001),"⬆ Spike","⬇ Drop"), "Normal") -> Normal | X28: Atemp vs Cnt | Z28: =CORREL(K:K,P:P) -> 0.17826434
A29: 28 | B29: 40545 | C29: 1 | D29: 0 | E29: 1 | F29: 3 | G29: FALSE | H29: 0 | I29: 2 | J29: 0.46 | K29: 0.4545 | L29: 0.94 | M29: 0.194 | N29: 2 | O29: 4 | P29: 6 | Q29: Monday | R29: More Than Mild | S29: =IF(OR(AND(F29>=7,F29<=9),AND(F29>=17,F29<=19)),"Rush Hour","Normal") -> Normal | T29: =IF(P29>150,"High",IF(P29>50,"Medium","Low")) -> Low | U29: =IF(F29<6,"Night", IF(F29<12,"Morning", IF(F29<18,"Afternoon","Evening"))) -> Night | V29: =IF(J29<0.1,"Freezing (0-10%)", IF(J29<0.2,"Very Cold (10-20%)", IF(J29<0.3,"Cold (20-30%)", IF(J29<0.4,"Mild (30-40%)", IF(J29<0.5,"Warm (40-50%)", "Hot (50%+)"))))) -> Warm (40-50%) | W29: =IF(ABS(P29-AVERAGE($P$2:$P$1001))>2*STDEV($P$2:$P$1001),IF(P29>AVERAGE($P$2:$P$1001),"⬆ Spike","⬇ Drop"), "Normal") -> Normal | X29: Humidity vs Cnt | Z29: =CORREL(L:L,P:P) -> -0.2543533
A30: 29 | B30: 40545 | C30: 1 | D30: 0 | E30: 1 | F30: 4 | G30: FALSE | H30: 0 | I30: 2 | J30: 0.46 | K30: 0.4091 | L30: 0.94 | M30: 0.194 | N30: 2 | O30: 1 | P30: 3 | Q30: Monday | R30: More Than Mild | S30: =IF(OR(AND(F30>=7,F30<=9),AND(F30>=17,F30<=19)),"Rush Hour","Normal") -> Normal | T30: =IF(P30>150,"High",IF(P30>50,"Medium","Low")) -> Low | U30: =IF(F30<6,"Night", IF(F30<12,"Morning", IF(F30<18,"Afternoon","Evening"))) -> Night | V30: =IF(J30<0.1,"Freezing (0-10%)", IF(J30<0.2,"Very Cold (10-20%)", IF(J30<0.3,"Cold (20-30%)", IF(J30<0.4,"Mild (30-40%)", IF(J30<0.5,"Warm (40-50%)", "Hot (50%+)"))))) -> Warm (40-50%) | W30: =IF(ABS(P30-AVERAGE($P$2:$P$1001))>2*STDEV($P$2:$P$1001),IF(P30>AVERAGE($P$2:$P$1001),"⬆ Spike","⬇ Drop"), "Normal") -> Normal | X30: Windspeed vs Cnt | Z30: =CORREL(M:M,P:P) -> 0.10399668
A31: 30 | B31: 40545 | C31: 1 | D31: 0 | E31: 1 | F31: 6 | G31: FALSE | H31: 0 | I31: 3 | J31: 0.42 | K31: 0.4242 | L31: 0.77 | M31: 0.2985 | N31: 0 | O31: 2 | P31: 2 | Q31: Monday | R31: Dark Cloude | S31: =IF(OR(AND(F31>=7,F31<=9),AND(F31>=17,F31<=19)),"Rush Hour","Normal") -> Normal | T31: =IF(P31>150,"High",IF(P31>50,"Medium","Low")) -> Low | U31: =IF(F31<6,"Night", IF(F31<12,"Morning", IF(F31<18,"Afternoon","Evening"))) -> Morning | V31: =IF(J31<0.1,"Freezing (0-10%)", IF(J31<0.2,"Very Cold (10-20%)", IF(J31<0.3,"Cold (20-30%)", IF(J31<0.4,"Mild (30-40%)", IF(J31<0.5,"Warm (40-50%)", "Hot (50%+)"))))) -> Warm (40-50%) | W31: =IF(ABS(P31-AVERAGE($P$2:$P$1001))>2*STDEV($P$2:$P$1001),IF(P31>AVERAGE($P$2:$P$1001),"⬆ Spike","⬇ Drop"), "Normal") -> Normal
A32: 31 | B32: 40545 | C32: 1 | D32: 0 | E32: 1 | F32: 7 | G32: FALSE | H32: 0 | I32: 2 | J32: 0.4 | K32: 0.4091 | L32: 0.76 | M32: 0.194 | N32: 0 | O32: 1 | P32: 1 | Q32: Monday | R32: More Than Mild | S32: =IF(OR(AND(F32>=7,F32<=9),AND(F32>=17,F32<=19)),"Rush Hour","Normal") -> Rush Hour | T32: =IF(P32>150,"High",IF(P32>50,"Medium","Low")) -> Low | U32: =IF(F32<6,"Night", IF(F32<12,"Morning", IF(F32<18,"Afternoon","Evening"))) -> Morning | V32: =IF(J32<0.1,"Freezing (0-10%)", IF(J32<0.2,"Very Cold (10-20%)", IF(J32<0.3,"Cold (20-30%)", IF(J32<0.4,"Mild (30-40%)", IF(J32<0.5,"Warm (40-50%)", "Hot (50%+)"))))) -> Warm (40-50%) | W32: =IF(ABS(P32-AVERAGE($P$2:$P$1001))>2*STDEV($P$2:$P$1001),IF(P32>AVERAGE($P$2:$P$1001),"⬆ Spike","⬇ Drop"), "Normal") -> Normal | X32: High demand hours count:
A33: 32 | B33: 40545 | C33: 1 | D33: 0 | E33: 1 | F33: 8 | G33: FALSE | H33: 0 | I33: 3 | J33: 0.4 | K33: 0.4091 | L33: 0.71 | M33: 0.2239 | N33: 0 | O33: 8 | P33: 8 | Q33: Monday | R33: Dark Cloude | S33: =IF(OR(AND(F33>=7,F33<=9),AND(F33>=17,F33<=19)),"Rush Hour","Normal") -> Rush Hour | T33: =IF(P33>150,"High",IF(P33>50,"Medium","Low")) -> Low | U33: =IF(F33<6,"Night", IF(F33<12,"Morning", IF(F33<18,"Afternoon","Evening"))) -> Morning | V33: =IF(J33<0.1,"Freezing (0-10%)", IF(J33<0.2,"Very Cold (10-20%)", IF(J33<0.3,"Cold (20-30%)", IF(J33<0.4,"Mild (30-40%)", IF(J33<0.5,"Warm (40-50%)", "Hot (50%+)"))))) -> Warm (40-50%) | W33: =IF(ABS(P33-AVERAGE($P$2:$P$1001))>2*STDEV($P$2:$P$1001),IF(P33>AVERAGE($P$2:$P$1001),"⬆ Spike","⬇ Drop"), "Normal") -> Normal | X33: How many hours had high demand | Z33: =COUNTIF(T:T, "High") -> 77
A34: 33 | B34: 40545 | C34: 1 | D34: 0 | E34: 1 | F34: 9 | G34: FALSE | H34: 0 | I34: 2 | J34: 0.38 | K34: 0.4545 | L34: 0.76 | M34: 0.2239 | N34: 1 | O34: 19 | P34: 20 | Q34: Monday | R34: More Than Mild | S34: =IF(OR(AND(F34>=7,F34<=9),AND(F34>=17,F34<=19)),"Rush Hour","Normal") -> Rush Hour | T34: =IF(P34>150,"High",IF(P34>50,"Medium","Low")) -> Low | U34: =IF(F34<6,"Night", IF(F34<12,"Morning", IF(F34<18,"Afternoon","Evening"))) -> Morning | V34: =IF(J34<0.1,"Freezing (0-10%)", IF(J34<0.2,"Very Cold (10-20%)", IF(J34<0.3,"Cold (20-30%)", IF(J34<0.4,"Mild (30-40%)", IF(J34<0.5,"Warm (40-50%)", "Hot (50%+)"))))) -> Mild (30-40%) | W34: =IF(ABS(P34-AVERAGE($P$2:$P$1001))>2*STDEV($P$2:$P$1001),IF(P34>AVERAGE($P$2:$P$1001),"⬆ Spike","⬇ Drop"), "Normal") -> Normal | X34: Medium demand hours | Z34: =COUNTIF(T:T, "Medium") -> 416
A35: 34 | B35: 40545 | C35: 1 | D35: 0 | E35: 1 | F35: 10 | G35: FALSE | H35: 0 | I35: 2 | J35: 0.36 | K35: 0.3485 | L35: 0.81 | M35: 0.2239 | N35: 7 | O35: 46 | P35: 53 | Q35: Monday | R35: More Than Mild | S35: =IF(OR(AND(F35>=7,F35<=9),AND(F35>=17,F35<=19)),"Rush Hour","Normal") -> Normal | T35: =IF(P35>150,"High",IF(P35>50,"Medium","Low")) -> Medium | U35: =IF(F35<6,"Night", IF(F35<12,"Morning", IF(F35<18,"Afternoon","Evening"))) -> Morning | V35: =IF(J35<0.1,"Freezing (0-10%)", IF(J35<0.2,"Very Cold (10-20%)", IF(J35<0.3,"Cold (20-30%)", IF(J35<0.4,"Mild (30-40%)", IF(J35<0.5,"Warm (40-50%)", "Hot (50%+)"))))) -> Mild (30-40%) | W35: =IF(ABS(P35-AVERAGE($P$2:$P$1001))>2*STDEV($P$2:$P$1001),IF(P35>AVERAGE($P$2:$P$1001),"⬆ Spike","⬇ Drop"), "Normal") -> Normal | X35: low demand hours | Z35: =COUNTIF(T:T, "Low") -> 507
A36: 35 | B36: 40545 | C36: 1 | D36: 0 | E36: 1 | F36: 11 | G36: FALSE | H36: 0 | I36: 2 | J36: 0.36 | K36: 0.3333 | L36: 0.71 | M36: 0.2537 | N36: 16 | O36: 54 | P36: 70 | Q36: Monday | R36: More Than Mild | S36: =IF(OR(AND(F36>=7,F36<=9),AND(F36>=17,F36<=19)),"Rush Hour","Normal") -> Normal | T36: =IF(P36>150,"High",IF(P36>50,"Medium","Low")) -> Medium | U36: =IF(F36<6,"Night", IF(F36<12,"Morning", IF(F36<18,"Afternoon","Evening"))) -> Morning | V36: =IF(J36<0.1,"Freezing (0-10%)", IF(J36<0.2,"Very Cold (10-20%)", IF(J36<0.3,"Cold (20-30%)", IF(J36<0.4,"Mild (30-40%)", IF(J36<0.5,"Warm (40-50%)", "Hot (50%+)"))))) -> Mild (30-40%) | W36: =IF(ABS(P36-AVERAGE($P$2:$P$1001))>2*STDEV($P$2:$P$1001),IF(P36>AVERAGE($P$2:$P$1001),"⬆ Spike","⬇ Drop"), "Normal") -> Normal
A37: 36 | B37: 40545 | C37: 1 | D37: 0 | E37: 1 | F37: 12 | G37: FALSE | H37: 0 | I37: 2 | J37: 0.36 | K37: 0.3333 | L37: 0.66 | M37: 0.2985 | N37: 20 | O37: 73 | P37: 93 | Q37: Monday | R37: More Than Mild | S37: =IF(OR(AND(F37>=7,F37<=9),AND(F37>=17,F37<=19)),"Rush Hour","Normal") -> Normal | T37: =IF(P37>150,"High",IF(P37>50,"Medium","Low")) -> Medium | U37: =IF(F37<6,"Night", IF(F37<12,"Morning", IF(F37<18,"Afternoon","Evening"))) -> Afternoon | V37: =IF(J37<0.1,"Freezing (0-10%)", IF(J37<0.2,"Very Cold (10-20%)", IF(J37<0.3,"Cold (20-30%)", IF(J37<0.4,"Mild (30-40%)", IF(J37<0.5,"Warm (40-50%)", "Hot (50%+)"))))) -> Mild (30-40%) | W37: =IF(ABS(P37-AVERAGE($P$2:$P$1001))>2*STDEV($P$2:$P$1001),IF(P37>AVERAGE($P$2:$P$1001),"⬆ Spike","⬇ Drop"), "Normal") -> Normal | X37: Rush hour vs normal:
A38: 37 | B38: 40545 | C38: 1 | D38: 0 | E38: 1 | F38: 13 | G38: FALSE | H38: 0 | I38: 2 | J38: 0.36 | K38: 0.3485 | L38: 0.66 | M38: 0.1343 | N38: 11 | O38: 64 | P38: 75 | Q38: Monday | R38: More Than Mild | S38: =IF(OR(AND(F38>=7,F38<=9),AND(F38>=17,F38<=19)),"Rush Hour","Normal") -> Normal | T38: =IF(P38>150,"High",IF(P38>50,"Medium","Low")) -> Medium | U38: =IF(F38<6,"Night", IF(F38<12,"Morning", IF(F38<18,"Afternoon","Evening"))) -> Afternoon | V38: =IF(J38<0.1,"Freezing (0-10%)", IF(J38<0.2,"Very Cold (10-20%)", IF(J38<0.3,"Cold (20-30%)", IF(J38<0.4,"Mild (30-40%)", IF(J38<0.5,"Warm (40-50%)", "Hot (50%+)"))))) -> Mild (30-40%) | W38: =IF(ABS(P38-AVERAGE($P$2:$P$1001))>2*STDEV($P$2:$P$1001),IF(P38>AVERAGE($P$2:$P$1001),"⬆ Spike","⬇ Drop"), "Normal") -> Normal | X38: Avg rides during rush hour | Z38: =AVERAGEIF(S:S, "Rush Hour",P:P) -> 103.15953
A39: 38 | B39: 40545 | C39: 1 | D39: 0 | E39: 1 | F39: 14 | G39: FALSE | H39: 0 | I39: 3 | J39: 0.36 | K39: 0.4242 | L39: 0.76 | M39: 0.194 | N39: 4 | O39: 55 | P39: 59 | Q39: Monday | R39: Dark Cloude | S39: =IF(OR(AND(F39>=7,F39<=9),AND(F39>=17,F39<=19)),"Rush Hour","Normal") -> Normal | T39: =IF(P39>150,"High",IF(P39>50,"Medium","Low")) -> Medium | U39: =IF(F39<6,"Night", IF(F39<12,"Morning", IF(F39<18,"Afternoon","Evening"))) -> Afternoon | V39: =IF(J39<0.1,"Freezing (0-10%)", IF(J39<0.2,"Very Cold (10-20%)", IF(J39<0.3,"Cold (20-30%)", IF(J39<0.4,"Mild (30-40%)", IF(J39<0.5,"Warm (40-50%)", "Hot (50%+)"))))) -> Mild (30-40%) | W39: =IF(ABS(P39-AVERAGE($P$2:$P$1001))>2*STDEV($P$2:$P$1001),IF(P39>AVERAGE($P$2:$P$1001),"⬆ Spike","⬇ Drop"), "Normal") -> Normal | X39: Avg rides during normal hours | Z39: =AVERAGEIF(S:S, "Normal",P:P) -> 42.788694
A40: 39 | B40: 40545 | C40: 1 | D40: 0 | E40: 1 | F40: 15 | G40: FALSE | H40: 0 | I40: 3 | J40: 0.34 | K40: 0.3333 | L40: 0.81 | M40: 0.1642 | N40: 19 | O40: 55 | P40: 74 | Q40: Monday | R40: Dark Cloude | S40: =IF(OR(AND(F40>=7,F40<=9),AND(F40>=17,F40<=19)),"Rush Hour","Normal") -> Normal | T40: =IF(P40>150,"High",IF(P40>50,"Medium","Low")) -> Medium | U40: =IF(F40<6,"Night", IF(F40<12,"Morning", IF(F40<18,"Afternoon","Evening"))) -> Afternoon | V40: =IF(J40<0.1,"Freezing (0-10%)", IF(J40<0.2,"Very Cold (10-20%)", IF(J40<0.3,"Cold (20-30%)", IF(J40<0.4,"Mild (30-40%)", IF(J40<0.5,"Warm (40-50%)", "Hot (50%+)"))))) -> Mild (30-40%) | W40: =IF(ABS(P40-AVERAGE($P$2:$P$1001))>2*STDEV($P$2:$P$1001),IF(P40>AVERAGE($P$2:$P$1001),"⬆ Spike","⬇ Drop"), "Normal") -> Normal
...

Sheet D1How Many Hours weather occ
A3: Row Labels | B3: Count of instant
A4: Sunday | B4: 95
A5: Dark Cloude | B5: 6
A6: MildCold | B6: 50
A7: More Then Mild | B7: 39
A8: Monday | B8: 94
A9: Dark Cloude | B9: 5
A10: MildCold | B10: 70
A11: More Then Mild | B11: 19
A12: Tuesday | B12: 93
A13: Dark Cloude | B13: 5
A14: MildCold | B14: 57
A15: More Then Mild | B15: 31
... A31: More Then Mild | B31: 23
A32: (blank)
A33: (blank)
A34: Grand Total | B34: 610

Sheet D3 Demand By Hour
A3: Row Labels | B3: Average of cnt | C3: Average of casual | D3: Average of registered
A4: 0 | B4: 19.588235 | C4: 1.8823529 | D4: 17.705882
A5: 1 | B5: 13 | C5: 1.1764706 | D5: 11.823529
A6: 2 | B6: 7.2941176 | C6: 0.88235294 | D6: 6.4117647
A7: 3 | B7: 5 | C7: 1.0666667 | D7: 3.9333333
A8: 4 | B8: 2.5833333 | C8: 0.16666667 | D8: 2.4166667
A9: 5 | B9: 4.6 | C9: 0.066666667 | D9: 4.5333333
A10: 6 | B10: 21.625 | C10: 0.5625 | D10: 21.0625
A11: 7 | B11: 55.647059 | C11: 1.2941176 | D11: 54.352941
A12: 8 | B12: 129.375 | C12: 2.9375 | D12: 126.4375
A13: 9 | B13: 92.25 | C13: 4.3125 | D13: 87.9375
A14: 10 | B14: 59.5 | C14: 5.9375 | D14: 53.5625
A15: 11 | B15: 64.9375 | C15: 9.0625 | D15: 55.875
... A27: 23 | B27: 30.764706 | C27: 2.9411765 | D27: 27.823529
A28: (blank)
A29: Grand Total | B29: 62.579487 | C29: 5.5769231 | D29: 57.002564

Sheet D3Demand by Weather
A3: Row Labels | B3: Average of cnt | C3: Sum of casual | D3: Sum of registered
A4: 1 | B4: 64.705882 | C4: 1568 | D4: 13832
A5: 2 | B5: 66.782609 | C5: 537 | D5: 7143
A6: 3 | B6: 35.837838 | C6: 70 | D6: 1256
A7: (blank)
A8: Grand Total | B8: 62.579487 | C8: 2175 | D8: 22231

Sheet D 3Demand by weekday
A3: Average of cnt | B3: Column Labels
A4: Row Labels | B4: 1 | C4: 2 | D4: 3 | E4: (blank) | F4: Grand Total
A5: 0 | B5: 66.660377 | C5: 45.588235 | F5: 61.542857
A6: 1 | B6: 29.107143 | C6: 92.884615 | D6: 67 | F6: 60.071429
A7: 2 | B7: 77 | C7: 54.454545 | D7: 38.166667 | F7: 61.489362
A8: 3 | B8: 72.869565 | C8: 87.636364 | D8: 37.769231 | F8: 66.617021
A9: 4 | B9: 75.725 | C9: 11 | D9: 8.6666667 | F9: 67.130435
A10: 5 | B10: 83.466667 | C10: 67.217391 | F10: 76.415094
A11: 6 | B11: 52.888889 | C11: 57.615385 | D11: 34.307692 | F11: 50.352113
A12: (blank)
A13: Grand Total | B13: 64.705882 | C13: 66.782609 | D13: 35.837838 | F13: 62.579487

Sheet D3 Hr Vs Day Vs Avg Cnt
A3: Average of cnt | B3: Column Labels
A4: Row Labels | B4: 0 | C4: 1 | D4: 2 | E4: 3 | F4: 4 | G4: 5 | H4: 6 | I4: (blank) | J4: Grand Total
A5: 0 | B5: 37 | C5: 11 | D5: 9 | E5: 9.5 | F5: 14 | G5: 13.5 | H5: 32.333333 | J5: 19.588235
A6: 1 | B6: 32.333333 | C6: 6.3333333 | D6: 3.5 | E6: 5 | F6: 6 | G6: 7 | H6: 20.666667 | J6: 13
A7: 2 | B7: 17 | C7: 2 | D7: 2 | E7: 3.5 | F7: 2.5 | G7: 2 | H7: 15.666667 | J7: 7.2941176
A8: 3 | B8: 11 | C8: 1.6666667 | D8: 1.5 | E8: 1.5 | F8: 1 | G8: 1 | H8: 9.6666667 | J8: 5
A9: 4 | B9: 1.6666667 | C9: 2 | D9: 3 | E9: 1 | F9: 1 | H9: 5 | J9: 2.5833333
A10: 5 | B10: 2 | C10: 7 | D10: 2.5 | E10: 5 | F10: 4 | G10: 5.5 | H10: 5 | J10: 4.6
A11: 6 | B11: 3 | C11: 31 | D11: 30.5 | E11: 30.5 | F11: 32.5 | G11: 26 | H11: 2.6666667 | J11: 21.625
A12: 7 | B12: 4.6666667 | C12: 88.333333 | D12: 76 | E12: 74 | F12: 93 | G12: 80.5 | H12: 6.6666667 | J12: 55.647059
A13: 8 | B13: 15.666667 | C13: 207.5 | D13: 189 | E13: 177 | F13: 183 | G13: 218 | H13: 24.666667 | J13: 129.375
A14: 9 | B14: 43.333333 | C14: 115 | D14: 125.5 | E14: 123 | F14: 127.5 | G14: 133.5 | H14: 32.333333 | J14: 92.25
A15: 10 | B15: 86 | C15: 62 | D15: 47.5 | E15: 60 | F15: 43.5 | G15: 47.5 | H15: 57.666667 | J15: 59.5
A16: 11 | B16: 96 | C16: 47.5 | D16: 50.5 | E16: 46.5 | F16: 54.5 | G16: 64 | H16: 75 | J16: 64.9375
A17: 12 | B17: 141 | C17: 67 | D17: 60 | E17: 62.5 | F17: 69 | G17: 78.5 | H17: 83.333333 | J17: 84.1875
A18: 13 | B18: 140 | C18: 59 | D18: 51 | E18: 72 | F18: 56.5 | G18: 96 | H18: 90.666667 | J18: 85.0625
A19: 14 | B19: 148 | C19: 73 | D19: 59 | E19: 60.5 | F19: 47.5 | G19: 87.5 | H19: 91.333333 | J19: 85.8125
A20: 15 | B20: 151 | C20: 47 | D20: 51.5 | E20: 70 | F20: 55 | G20: 82 | H20: 118 | J20: 88.625
A21: 16 | B21: 138 | C21: 100 | D21: 73.5 | E21: 91 | F21: 79 | G21: 101.33333 | H21: 107.66667 | J21: 101.64706
... A28: 23 | B28: 27 | C28: 21 | D28: 14 | E28: 34.5 | F28: 36 | G28: 35.666667 | H28: 41.333333 | J28: 30.764706
A29: (blank)
A30: Grand Total | B30: 61.542857 | C30: 60.071429 | D30: 61.489362 | E30: 66.617021 | F30: 67.130435 | G30: 76.415094 | H30: 50.352113 | J30: 62.579487

Sheet D3Register Vs Casual
A3: Average of cnt | B3: Column Labels
A4: Row Labels | B4: 0 | C4: 1 | D4: 2 | E4: 3 | F4: 4 | G4: 5 | H4: 6 | I4: 7 | J4: 8 | K4: 9 | L4: 10 | M4: 11 | N4: 12 | O4: 13 | P4: 14 | Q4: 15 | R4: 16 | S4: 17 | T4: 19 | U4: 20 | V4: 21 | W4: 22 | X4: 23 | Y4: 25 | Z4: 26 | AA4: 27 | AB4: 28 | AC4: 29 | AD4: 30 | AE4: 31 | AF4: 32 | AG4: 33 | AH4: 34 | AI4: 35 | AJ4: 36 | AK4: 37 | AL4: 38 | AM4: 39 | AN4: 40 | AO4: 41 | AP4: 42 | AQ4: 43 | AR4: 44 | AS4: 45 | AT4: 46 | AU4: 47 | AV4: 48 | AW4: 49 | AX4: 50 | AY4: 51 | AZ4: 52 | BA4: 53 | BB4: 54 | BC4: 55 | BD4: 56 | BE4: 57 | BF4: 59 | BG4: 60 | BH4: 61 | BI4: 62 | BJ4: 63 | BK4: 64 | BL4: 65 | BM4: 66 | BN4: 67 | BO4: 68 | BP4: 69 | BQ4: 70 | BR4: 71 | BS4: 72 | BT4: 73 | BU4: 74 | BV4: 75 | BW4: 76 | BX4: 78 | BY4: 79 | BZ4: 81 | CA4: 82 | CB4: 83 | CC4: 84 | CD4: 85 | CE4: 86 | CF4: 87 | CG4: 88 | CH4: 89 | CI4: 90 | CJ4: 91 | CK4: 92 | CL4: 93 | CM4: 94 | CN4: 95 | CO4: 96 | CP4: 97 | CQ4: 98 | CR4: 99 | CS4: 100 | CT4: 102 | CU4: 103 | CV4: 104 | CW4: 105 | CX4: 106 | CY4: 107 | CZ4: 108 | DA4: 110 | DB4: 111 | DC4: 112 | DD4: 113 | DE4: 114 | DF4: 115 | DG4: 119 | DH4: 121 | DI4: 122 | DJ4: 123 | DK4: 124 | DL4: 126 | DM4: 127 | DN4: 128 | DO4: 130 | DP4: 132 | DQ4: 135 | DR4: 145 | DS4: 147 | DT4: 151 | DU4: 152 | DV4: 153 | DW4: 154 | DX4: 155 | DY4: 157 | DZ4: 159 | EA4: 165 | EB4: 168 | EC4: 170 | ED4: 172 | EE4: 173 | EF4: 175 | EG4: 182 | EH4: 183 | EI4: 184 | EJ4: 193 | EK4: 195 | EL4: 198 | EM4: 207 | EN4: 212 | EO4: 217 | EP4: 223 | EQ4: 236 | ER4: (blank) | ES4: Grand Total
A5: 0 | C5: 1 | D5: 2 | E5: 3 | F5: 4 | G5: 5 | H5: 6 | I5: 7 | J5: 8 | K5: 9 | L5: 10 | Q5: 15 | R5: 16 | S5: 17 | U5: 20 | W5: 22 | Z5: 26 | AC5: 29 | AG5: 33 | AH5: 34 | AK5: 37 | AM5: 39 | AQ5: 43 | AU5: 47 | AX5: 50 | AZ5: 52 | BK5: 64 | BX5: 78 | CB5: 83 | CC5: 84 | CF5: 87 | CR5: 99 | DC5: 112 | ES5: 17.216867
A6: 1 | C6: 2 | D6: 3 | F6: 5 | H6: 7 | I6: 8 | K6: 10 | L6: 11 | M6: 12 | P6: 15 | Q6: 16 | S6: 18 | T6: 20 | U6: 21 | W6: 23 | X6: 24 | Y6: 26 | AC6: 30 | AD6: 31 | AE6: 32 | AG6: 34 | AH6: 35 | AI6: 36 | AM6: 40 | AN6: 41 | AP6: 43 | AR6: 45 | AS6: 46 | AT6: 47 | AV6: 49 | AW6: 50 | BA6: 54 | BE6: 58 | BH6: 62 | BI6: 63 | BO6: 69 | BR6: 72 | BT6: 74 | BU6: 75 | CD6: 86 | CE6: 87 | CF6: 88 | CS6: 101 | CT6: 103 | CZ6: 109 | DH6: 122 | DT6: 152 | DW6: 155 | EL6: 199 | ES6: 43.622951
A7: 2 | E7: 5 | G7: 7 | H7: 8 | K7: 11 | N7: 14 | O7: 15 | Q7: 17 | T7: 21 | V7: 23 | W7: 24 | Z7: 28 | AB7: 30 | AH7: 36 | AK7: 39 | AM7: 41 | AO7: 43 | AQ7: 45 | AT7: 48 | AV7: 50 | AW7: 51 | AX7: 52 | AZ7: 54 | BA7: 55 | BD7: 58 | BF7: 61 | BH7: 63 | BJ7: 65 | BN7: 69 | BP7: 71 | BQ7: 72 | BZ7: 83 | CO7: 98 | CY7: 109 | DA7: 112 | DE7: 116 | DR7: 147 | DS7: 149 | EB7: 170 | ES7: 55.906977
A8: 3 | G8: 8 | I8: 10 | J8: 11 | K8: 12 | L8: 13 | S8: 20 | Y8: 28 | AA8: 30 | AC8: 32 | AD8: 33 | AE8: 34 | AH8: 37 | AJ8: 39 | AO8: 44 | AW8: 52 | BA8: 56 | BF8: 62 | BH8: 64 | BV8: 78 | CB8: 86 | CG8: 91 | CP8: 100 | CW8: 108 | CZ8: 111 | DF8: 118 | DK8: 127 | DP8: 135 | DU8: 155 | DV8: 156 | DY8: 160 | EA8: 168 | EG8: 185 | EO8: 220 | ES8: 71.186047
A9: 4 | B9: 4 | H9: 10 | J9: 12 | Z9: 30 | AB9: 32 | AH9: 38 | AN9: 44 | AP9: 46 | AQ9: 47 | AR9: 48 | AT9: 50 | AU9: 51 | AY9: 55 | BD9: 60 | BE9: 61 | BG9: 64 | BL9: 69 | BR9: 75 | BW9: 80 | BY9: 83 | CK9: 96 | CL9: 97 | CN9: 99 | DG9: 123 | ED9: 176 | EI9: 188 | EN9: 216 | ES9: 75.1875
A10: 5 | N10: 17 | R10: 21 | V10: 26 | W10: 27 | AE10: 36 | AH10: 39 | AI10: 40 | AL10: 43 | AM10: 44 | AT10: 51 | AU10: 52 | AV10: 53 | AW10: 54 | AX10: 55 | BE10: 62 | BK10: 69 | BP10: 74 | BT10: 78 | CC10: 89 | DJ10: 128 | EC10: 175 | EE10: 178 | ES10: 68.956522
A11: 6 | T11: 25 | AM11: 45 | AP11: 48 | AS11: 51 | AW11: 55 | AZ11: 58 | BI11: 68 | BR11: 77 | BX11: 84 | CA11: 88 | CH11: 95 | DM11: 133 | DX11: 161 | DZ11: 165 | ES11: 80.266667
A12: 7 | W12: 29 | AL12: 45 | AS12: 52 | AZ12: 59 | BE12: 64 | BF12: 66 | BK12: 71 | BS12: 79 | CM12: 101 | DN12: 135 | EF12: 182 | EH12: 190 | EP12: 230 | EQ12: 243 | ES12: 110.42857
A13: 8 | AT13: 54 | AY13: 59 | AZ13: 60 | BE13: 65 | BJ13: 71 | BX13: 86 | CJ13: 99 | CN13: 103 | DP13: 140 | ES13: 81.888889
A14: 9 | AP14: 51 | AT14: 55 | AX14: 59 | BC14: 64 | BD14: 65 | BF14: 68 | BT14: 82 | BZ14: 90 | CA14: 91 | DY14: 166 | EA14: 174 | EM14: 216 | ES14: 98.416667
A15: 10 | AP15: 52 | BB15: 64 | BI15: 72 | BM15: 76 | BQ15: 80 | CF15: 97 | CH15: 99 | EK15: 205 | ES15: 93.125
A16: 11 | AJ16: 47 | AW16: 60 | AX16: 61 | ES16: 56
A17: 12 | AI17: 47 | AZ17: 64 | BI17: 74 | BM17: 78 | ES17: 65.75
A18: 13 | BL18: 78 | BR18: 84 | ES18: 82
A19: 14 | BK19: 78 | CN19: 109 | DB19: 125 | ES19: 104
A20: 15 | AF20: 47 | BU20: 89 | BW20: 91 | ES20: 75.666667
A21: 16 | CQ21: 114 | ES21: 114
A22: 17 | BN22: 84 | BX22: 95 | ES22: 89.5
A23: 18 | CV23: 122 | EJ23: 211 | ES23: 166.5
A24: 19 | CE24: 105 | CG24: 107 | CV24: 123 | ES24: 111.66667
A25: 21 | CH25: 110 | ES25: 110
A26: 22 | CQ26: 120 | ES26: 120
A27: 24 | CP27: 121 | DD27: 137 | ES27: 129
A28: 26 | CE28: 112 | ES28: 112
A29: 27 | CL29: 120 | ES29: 120
A30: 28 | CH30: 117 | CX30: 134 | ES30: 125.5
A31: 30 | CC31: 114 | CI31: 120 | CN31: 125 | ES31: 119.66667
A32: 32 | CU32: 135 | ES32: 135
A33: 40 | DI33: 162 | ES33: 162
A34: 42 | CU34: 145 | DF34: 157 | ES34: 151
A35: 47 | DE35: 161 | DM35: 174 | DQ35: 182 | ES35: 172.33333
A36: 48 | DL36: 174 | ES36: 174
A37: 51 | DA37: 161 | ES37: 161
A38: 52 | DO38: 182 | ES38: 182
A39: 58 | CM39: 152 | ES39: 152
A40: 62 | CK40: 154 | ES40: 154
A41: (blank)
A42: Grand Total | B42: 4 | C42: 1.2352941 | D42: 2.125 | E42: 3.1538462 | F42: 4.2857143 | G42: 6.6666667 | H42: 7.5 | I42: 7.5714286 | J42: 9.4 | K42: 10.5 | L42: 11.6 | M42: 12 | N42: 15.5 | O42: 15 | P42: 15 | Q42: 16 | R42: 18.5 | S42: 18.25 | T42: 22 | U42: 20.333333 | V42: 24.5 | W42: 25 | X42: 24 | Y42: 27 | Z42: 27.6 | AA42: 30 | AB42: 31 | AC42: 30.333333 | AD42: 32.333333 | AE42: 34 | AF42: 47 | AG42: 33.5 | AH42: 36.375 | AI42: 41 | AJ42: 43 | AK42: 37.666667 | AL42: 44 | AM42: 41.285714 | AN42: 42.5 | AO42: 43.333333 | AP42: 48 | AQ42: 45 | AR42: 46.5 | AS42: 50 | AT42: 50.285714 | AU42: 50.25 | AV42: 50.666667 | AW42: 53.666667 | AX42: 55.4 | AY42: 57 | AZ42: 57.833333 | BA42: 55.4 | BB42: 64 | BC42: 64 | BD42: 61 | BE42: 62 | BF42: 64.25 | BG42: 64 | BH42: 63.5 | BI42: 69.25 | BJ42: 68 | BK42: 70.5 | BL42: 73.5 | BM42: 77 | BN42: 74 | BO42: 69 | BP42: 72.5 | BQ42: 76 | BR42: 78.4 | BS42: 79 | BT42: 78 | BU42: 82 | BV42: 78 | BW42: 85.5 | BX42: 85.75 | BY42: 83 | BZ42: 86.5 | CA42: 89.5 | CB42: 84.5 | CC42: 95.666667 | CD42: 86 | CE42: 101.33333 | CF42: 90.666667 | CG42: 99 | CH42: 105.25 | CI42: 120 | CJ42: 99 | CK42: 125 | CL42: 108.5 | CM42: 126.5 | CN42: 109 | CO42: 98 | CP42: 110.5 | CQ42: 117 | CR42: 99 | CS42: 101 | CT42: 103 | CU42: 140 | CV42: 122.5 | CW42: 108 | CX42: 134 | CY42: 109 | CZ42: 110 | DA42: 136.5 | DB42: 125 | DC42: 112 | DD42: 137 | DE42: 138.5 | DF42: 137.5 | DG42: 123 | DH42: 122 | DI42: 162 | DJ42: 128 | DK42: 127 | DL42: 174 | DM42: 153.5 | DN42: 135 | DO42: 182 | DP42: 137.5 | DQ42: 182 | DR42: 147 | DS42: 149 | DT42: 152 | DU42: 155 | DV42: 156 | DW42: 155 | DX42: 161 | DY42: 163 | DZ42: 165 | EA42: 171 | EB42: 170 | EC42: 175 | ED42: 176 | EE42: 178 | EF42: 182 | EG42: 185 | EH42: 190 | EI42: 188 | EJ42: 211 | EK42: 205 | EL42: 199 | EM42: 216 | EN42: 216 | EO42: 220 | EP42: 230 | EQ42: 243 | ES42: 62.579487

Sheet DatasetA CNT Count VS Day time 
A3: Sum of cnt | B3: Column Labels
A4: Row Labels | B4: 40544 | C4: 40545 | D4: 40546 | E4: 40547 | F4: 40548 | G4: 40549 | H4: 40550 | I4: 40551 | J4: 40552 | K4: 40553 | L4: 40554 | M4: 40555 | N4: 40556 | O4: 40557 | P4: 40558 | Q4: 40559 | R4: 40560 | S4: 40561 | T4: 40562 | U4: 40563 | V4: 40564 | W4: 40565 | X4: 40566 | Y4: 40567 | Z4: 40568 | AA4: 40569 | AB4: 40570 | AC4: 40571 | AD4: (blank) | AE4: Grand Total
A5: Afternoon | B5: 554 | C5: 442 | D5: 504 | E5: 598 | F5: 553 | G5: 541 | H5: 528 | I5: 514 | J5: 466 | K5: 450 | L5: 431 | M5: 404 | N5: 477 | O5: 519 | P5: 648 | Q5: 630 | R5: 505 | S5: 274 | T5: 606 | U5: 639 | V5: 536 | W5: 482 | X5: 510 | Y5: 479 | Z5: 689 | AA5: 236 | AB5: 108 | AC5: 139 | AE5: 13462
A6: Evening | B6: 209 | C6: 153 | D6: 403 | E6: 442 | F6: 494 | G6: 467 | H6: 359 | I6: 206 | J6: 168 | K6: 404 | L6: 246 | M6: 386 | N6: 392 | O6: 414 | P6: 326 | Q6: 252 | R6: 229 | S6: 409 | T6: 495 | U6: 607 | V6: 371 | W6: 260 | X6: 208 | Y6: 458 | Z6: 628 | AB6: 323 | AE6: 9309
A7: Morning | B7: 119 | C7: 154 | D7: 431 | E7: 508 | F7: 534 | G7: 576 | H7: 592 | I7: 169 | J7: 134 | K7: 451 | L7: 562 | M7: 353 | N7: 516 | O7: 459 | P7: 200 | Q7: 226 | R7: 219 | T7: 527 | U7: 653 | V7: 600 | W7: 193 | X7: 207 | Y7: 464 | Z7: 642 | AA7: 237 | AC7: 413 | AE7: 10139
A8: Night | B8: 103 | C8: 52 | D8: 11 | E8: 14 | F8: 19 | G8: 22 | H8: 31 | I8: 70 | J8: 54 | K8: 16 | L8: 24 | M8: 19 | N8: 21 | O8: 29 | P8: 74 | Q8: 96 | R8: 47 | T8: 22 | U8: 28 | V8: 36 | W8: 46 | X8: 61 | Y8: 15 | Z8: 26 | AA8: 33 | AC8: 19 | AE8: 988
A9: (blank)
A10: Grand Total | B10: 985 | C10: 801 | D10: 1349 | E10: 1562 | F10: 1600 | G10: 1606 | H10: 1510 | I10: 959 | J10: 822 | K10: 1321 | L10: 1263 | M10: 1162 | N10: 1406 | O10: 1421 | P10: 1248 | Q10: 1204 | R10: 1000 | S10: 683 | T10: 1650 | U10: 1927 | V10: 1543 | W10: 981 | X10: 986 | Y10: 1416 | Z10: 1985 | AA10: 506 | AB10: 431 | AC10: 571 | AE10: 33898

Sheet DatasetA Ridesby Hour
A3: Row Labels | B3: Average of cnt | C3: Sum of casual | D3: Sum of registered
A4: 0 | B4: 14.230769 | C4: 42 | D4: 328
A5: 1 | B5: 9.1923077 | C5: 28 | D5: 211
A6: 2 | B6: 7.0833333 | C6: 18 | D6: 152
A7: 3 | B7: 4.75 | C7: 18 | D7: 58
A8: 4 | B8: 1.9 | C8: 5 | D8: 33
A9: 5 | B9: 3.9583333 | C9: 2 | D9: 93
A10: 6 | B10: 18.307692 | C10: 12 | D10: 464
A11: 7 | B11: 53.576923 | C11: 42 | D11: 1351
A12: 8 | B12: 127.61538 | C12: 80 | D12: 3238
A13: 9 | B13: 84.461538 | C13: 103 | D13: 2093
A14: 10 | B14: 50.038462 | C14: 121 | D14: 1180
A15: 11 | B15: 55.961538 | C15: 222 | D15: 1233
... A27: 23 | B27: 21.538462 | C27: 51 | D27: 509
A28: (blank)
A29: Grand Total | B29: 55.570492 | C29: 2746 | D29: 31152

Sheet DatasetA Rides by Weather
A3: Row Labels | B3: Sum of casual | C3: Sum of registered | D3: Average of cnt
A4: 1 | B4: 1643 | C4: 20330 | D4: 59.709239
A5: 2 | B5: 1001 | C5: 9425 | D5: 53.742268
